Workbook

Sheet Overview
B2: NEXORA INDUSTRIES LIMITED
B3: Complete Accounting Cycle in Excel | Journal > Ledger > Trial Balance > Income Statement > Balance Sheet
B4: Financial year: 1 July 2025 to 30 June 2026 | Currency: PKR | Prepared by: Jawad Ahmad
B6: PROJECT SUMMARY
B7: A fully formula-driven bookkeeping model for a start-up trading company. Every figure in the ledger, trial balance and financial statements flows from the General Journal, so changing one entry updates the whole workbook. Built-in checks confirm that debits equal credits and that the balance sheet balances.
B9: KEY RESULTS (live from the statements)
C10: Sales Revenue | E10: ='Income Statement'!D6 -> 1225000
C11: Gross Profit | E11: ='Income Statement'!D8 -> 735000
C12: Operating Profit | E12: ='Income Statement'!D16 -> 475000
C13: Net Profit after Tax | E13: ='Income Statement'!D18 -> 332500
C14: Total Assets | E14: ='Balance Sheet'!D16 -> 6225000
C15: Trial Balance check (0 = OK) | E15: ='Trial Balance'!H22 -> 0
C16: Balance Sheet check (0 = OK) | E16: ='Balance Sheet'!D29 -> 0
B18: WORKBOOK GUIDE
B19: 1 | C19: Chart of Accounts | D19: 15 accounts with code, category, sub-category and financial-statement mapping
B20: 2 | C20: General Journal | D20: All 14 double-entry journal entries (the only place with typed inputs)
B21: 3 | C21: Ledger | D21: Every account with running balance, pulled from the journal by formula
B22: 4 | C22: Trial Balance | D22: Totals and closing balances using SUMIF; confirms debits = credits
B23: 5 | C23: Income Statement | D23: Revenue, gross profit, operating profit, tax and net profit
B24: 6 | C24: Balance Sheet | D24: Assets vs liabilities + equity, with a balance check
B26: TRANSACTIONS RECORDED
B27: No. | C27: Date | D27: Transaction | E27: Amount (PKR)
B28: 1 | C28: 45839 | D28: Started business with cash | E28: 5000000
B29: 2 | C29: 45840 | D29: Deposited cash into bank | E29: 1500000
B30: 3 | C30: 45843 | D30: Inventory purchased on credit from Mega Mart | E30: 750000
B31: 4 | C31: 45845 | D31: Inventory purchased from Multi Media (paid via bank - assumed) | E31: 500000
B32: 5 | C32: 45848 | D32: Inventory sold on credit to Mr. Rehman | E32: 800000
B33: 6 | C33: 45852 | D33: Inventory sold for cash | E33: 425000
B34: 7 | C34: 45854 | D34: Office expenses incurred | E34: 45000
B35: 8 | C35: 45856 | D35: Entertainment expenses incurred | E35: 70000
B36: 9 | C36: 45865 | D36: Computer purchased | E36: 250000
B37: 10 | C37: 45870 | D37: Salary paid | E37: 110000
B38: 11 | C38: 45871 | D38: Rent paid to Mr. Abbas | E38: 35000
B39: 12 | C39: 45853 | D39: Adjustment: cost of goods sold (290,000 + 200,000) | E39: 490000
B40: 13 | C40: 46203 | D40: Adjustment: income tax provision @ 30% | E40: 142500
B42: ASSUMPTIONS
B43: 1 | C43: Payment method was not stated for the Multi Media purchase, computer, office, entertainment, salary and rent; all assumed paid through the bank account.
B44: 2 | C44: No depreciation is charged on computer equipment (simplified for this exercise).
B45: 3 | C45: Income tax is 30% of operating profit, provided at year end and shown as payable to the government.
B46: 4 | C46: Cost of goods sold of PKR 490,000 is recorded as two adjustment entries against inventory.
...

Sheet Chart of Accounts
B1: NEXORA INDUSTRIES LIMITED
B2: Chart of Accounts
B3: For the year ended 30 June 2026 | Amounts in PKR
B5: Code | C5: Account Name | D5: Category | E5: Sub-Category | F5: Financial Statement | G5: Normal Balance
B6: 1001 | C6: Cash in Hand | D6: Asset | E6: Current Assets | F6: Balance Sheet | G6: Debit
B7: 1002 | C7: Bank | D7: Asset | E7: Current Assets | F7: Balance Sheet | G7: Debit
B8: 1003 | C8: Inventory | D8: Asset | E8: Current Assets | F8: Balance Sheet | G8: Debit
B9: 1004 | C9: Accounts Receivable - Mr. Rehman | D9: Asset | E9: Current Assets | F9: Balance Sheet | G9: Debit
B10: 1101 | C10: Computer Equipment | D10: Asset | E10: Non-Current Assets | F10: Balance Sheet | G10: Debit
B11: 2001 | C11: Accounts Payable - Mega Mart | D11: Liability | E11: Current Liabilities | F11: Balance Sheet | G11: Credit
B12: 2002 | C12: Income Tax Payable (Govt) | D12: Liability | E12: Current Liabilities | F12: Balance Sheet | G12: Credit
B13: 3001 | C13: Owner's Capital | D13: Equity | E13: Equity | F13: Balance Sheet | G13: Credit
B14: 4001 | C14: Sales Revenue | D14: Revenue | E14: Revenue | F14: Income Statement | G14: Credit
B15: 5001 | C15: Cost of Goods Sold | D15: Expense | E15: Cost of Sales | F15: Income Statement | G15: Debit
B16: 5002 | C16: Office Expenses | D16: Expense | E16: Operating Expenses | F16: Income Statement | G16: Debit
B17: 5003 | C17: Entertainment Expenses | D17: Expense | E17: Operating Expenses | F17: Income Statement | G17: Debit
... B20: 5006 | C20: Income Tax Expense | D20: Expense | E20: Tax | F20: Income Statement | G20: Debit

Sheet General Journal
B1: NEXORA INDUSTRIES LIMITED
B2: General Journal
B3: For the year ended 30 June 2026 | Amounts in PKR
B5: JE No. | C5: Date | D5: Description | E5: Account | F5: Debit | G5: Credit | H5: Narration
B6: JE-01 | C6: 45839 | D6: Business started with cash | E6: Cash in Hand | F6: 5000000 | H6: Owner's capital introduced in cash
B7: JE-01 | C7: 45839 | D7: Business started with cash | E7: Owner's Capital | G7: =F6 -> 5000000
B8: JE-02 | C8: 45840 | D8: Cash deposited into bank | E8: Bank | F8: 1500000 | H8: Cash moved from hand to bank account
B9: JE-02 | C9: 45840 | D9: Cash deposited into bank | E9: Cash in Hand | G9: =F8 -> 1500000
B10: JE-03 | C10: 45843 | D10: Inventory purchased on credit | E10: Inventory | F10: 750000 | H10: Goods bought from Mega Mart on credit
B11: JE-03 | C11: 45843 | D11: Inventory purchased on credit | E11: Accounts Payable - Mega Mart | G11: =F10 -> 750000
B12: JE-04 | C12: 45845 | D12: Inventory purchased | E12: Inventory | F12: 500000 | H12: Goods bought from Multi Media (paid via bank - assumed)
B13: JE-04 | C13: 45845 | D13: Inventory purchased | E13: Bank | G13: =F12 -> 500000
B14: JE-05 | C14: 45848 | D14: Inventory sold on credit | E14: Accounts Receivable - Mr. Rehman | F14: 800000 | H14: Credit sale to Mr. Rehman
B15: JE-05 | C15: 45848 | D15: Inventory sold on credit | E15: Sales Revenue | G15: =F14 -> 800000
B16: JE-06 | C16: 45852 | D16: Inventory sold for cash | E16: Cash in Hand | F16: 425000 | H16: Cash sale
B17: JE-06 | C17: 45852 | D17: Inventory sold for cash | E17: Sales Revenue | G17: =F16 -> 425000
B18: JE-07 | C18: 45853 | D18: Cost of goods sold | E18: Cost of Goods Sold | F18: 290000 | H18: Cost of inventory sold (1 of 2)
B19: JE-07 | C19: 45853 | D19: Cost of goods sold | E19: Inventory | G19: =F18 -> 290000
B20: JE-08 | C20: 45853 | D20: Cost of goods sold | E20: Cost of Goods Sold | F20: 200000 | H20: Cost of inventory sold (2 of 2)
B21: JE-08 | C21: 45853 | D21: Cost of goods sold | E21: Inventory | G21: =F20 -> 200000
B22: JE-09 | C22: 45854 | D22: Office expenses incurred | E22: Office Expenses | F22: 45000 | H22: Office expenses paid via bank
B23: JE-09 | C23: 45854 | D23: Office expenses incurred | E23: Bank | G23: =F22 -> 45000
B24: JE-10 | C24: 45856 | D24: Entertainment expenses incurred | E24: Entertainment Expenses | F24: 70000 | H24: Entertainment expenses paid via bank
B25: JE-10 | C25: 45856 | D25: Entertainment expenses incurred | E25: Bank | G25: =F24 -> 70000
B26: JE-11 | C26: 45865 | D26: Computer purchased | E26: Computer Equipment | F26: 250000 | H26: Computer bought for business use (paid via bank)
B27: JE-11 | C27: 45865 | D27: Computer purchased | E27: Bank | G27: =F26 -> 250000
B28: JE-12 | C28: 45870 | D28: Salary paid | E28: Salary Expense | F28: 110000 | H28: Salary paid via bank
B29: JE-12 | C29: 45870 | D29: Salary paid | E29: Bank | G29: =F28 -> 110000
B30: JE-13 | C30: 45871 | D30: Rent paid to Mr. Abbas | E30: Rent Expense | F30: 35000 | H30: Rent paid via bank
B31: JE-13 | C31: 45871 | D31: Rent paid to Mr. Abbas | E31: Bank | G31: =F30 -> 35000
B32: JE-14 | C32: 46203 | D32: Income tax provision | E32: Income Tax Expense | F32: 142500 | H32: Year-end tax provision: 30% of operating profit (see Income Statement)
B33: JE-14 | C33: 46203 | D33: Income tax provision | E33: Income Tax Payable (Govt) | G33: =F32 -> 142500
E34: Total | F34: =SUM(F6:F33) -> 10117500 | G34: =SUM(G6:G33) -> 10117500
E35: Check (Debit - Credit, must be 0) | G35: =F34-G34 -> 0
B37: Blue = typed input (source transactions). Black = formula. Credit lines always mirror the debit line above them.

Sheet Ledger
B1: NEXORA INDUSTRIES LIMITED
B2: General Ledger (all accounts, running balance)
B3: For the year ended 30 June 2026 | Amounts in PKR
B5: 1001 - Cash in Hand
B6: Date | C6: Description | D6: Contra Account | E6: Debit | F6: Credit | G6: Balance
B7: ='General Journal'!C6 -> 45839 | C7: ='General Journal'!D6 -> Business started with cash | D7: ='General Journal'!E7 -> Owner's Capital | E7: ='General Journal'!F6 -> 5000000 | G7: =SUM($E$7:E7)-SUM($F$7:F7) -> 5000000
B8: ='General Journal'!C9 -> 45840 | C8: ='General Journal'!D9 -> Cash deposited into bank | D8: ='General Journal'!E8 -> Bank | F8: ='General Journal'!G9 -> 1500000 | G8: =SUM($E$7:E8)-SUM($F$7:F8) -> 3500000
B9: ='General Journal'!C16 -> 45852 | C9: ='General Journal'!D16 -> Inventory sold for cash | D9: ='General Journal'!E17 -> Sales Revenue | E9: ='General Journal'!F16 -> 425000 | G9: =SUM($E$7:E9)-SUM($F$7:F9) -> 3925000
D10: Closing balance | E10: =SUM(E7:E9) -> 5425000 | F10: =SUM(F7:F9) -> 1500000 | G10: =E10-F10 -> 3925000
B12: 1002 - Bank
B13: Date | C13: Description | D13: Contra Account | E13: Debit | F13: Credit | G13: Balance
B14: ='General Journal'!C8 -> 45840 | C14: ='General Journal'!D8 -> Cash deposited into bank | D14: ='General Journal'!E9 -> Cash in Hand | E14: ='General Journal'!F8 -> 1500000 | G14: =SUM($E$14:E14)-SUM($F$14:F14) -> 1500000
B15: ='General Journal'!C13 -> 45845 | C15: ='General Journal'!D13 -> Inventory purchased | D15: ='General Journal'!E12 -> Inventory | F15: ='General Journal'!G13 -> 500000 | G15: =SUM($E$14:E15)-SUM($F$14:F15) -> 1000000
B16: ='General Journal'!C23 -> 45854 | C16: ='General Journal'!D23 -> Office expenses incurred | D16: ='General Journal'!E22 -> Office Expenses | F16: ='General Journal'!G23 -> 45000 | G16: =SUM($E$14:E16)-SUM($F$14:F16) -> 955000
B17: ='General Journal'!C25 -> 45856 | C17: ='General Journal'!D25 -> Entertainment expenses incurred | D17: ='General Journal'!E24 -> Entertainment Expenses | F17: ='General Journal'!G25 -> 70000 | G17: =SUM($E$14:E17)-SUM($F$14:F17) -> 885000
B18: ='General Journal'!C27 -> 45865 | C18: ='General Journal'!D27 -> Computer purchased | D18: ='General Journal'!E26 -> Computer Equipment | F18: ='General Journal'!G27 -> 250000 | G18: =SUM($E$14:E18)-SUM($F$14:F18) -> 635000
B19: ='General Journal'!C29 -> 45870 | C19: ='General Journal'!D29 -> Salary paid | D19: ='General Journal'!E28 -> Salary Expense | F19: ='General Journal'!G29 -> 110000 | G19: =SUM($E$14:E19)-SUM($F$14:F19) -> 525000
B20: ='General Journal'!C31 -> 45871 | C20: ='General Journal'!D31 -> Rent paid to Mr. Abbas | D20: ='General Journal'!E30 -> Rent Expense | F20: ='General Journal'!G31 -> 35000 | G20: =SUM($E$14:E20)-SUM($F$14:F20) -> 490000
D21: Closing balance | E21: =SUM(E14:E20) -> 1500000 | F21: =SUM(F14:F20) -> 1010000 | G21: =E21-F21 -> 490000
B23: 1003 - Inventory
B24: Date | C24: Description | D24: Contra Account | E24: Debit | F24: Credit | G24: Balance
B25: ='General Journal'!C10 -> 45843 | C25: ='General Journal'!D10 -> Inventory purchased on credit | D25: ='General Journal'!E11 -> Accounts Payable - Mega Mart | E25: ='General Journal'!F10 -> 750000 | G25: =SUM($E$25:E25)-SUM($F$25:F25) -> 750000
B26: ='General Journal'!C12 -> 45845 | C26: ='General Journal'!D12 -> Inventory purchased | D26: ='General Journal'!E13 -> Bank | E26: ='General Journal'!F12 -> 500000 | G26: =SUM($E$25:E26)-SUM($F$25:F26) -> 1250000
B27: ='General Journal'!C19 -> 45853 | C27: ='General Journal'!D19 -> Cost of goods sold | D27: ='General Journal'!E18 -> Cost of Goods Sold | F27: ='General Journal'!G19 -> 290000 | G27: =SUM($E$25:E27)-SUM($F$25:F27) -> 960000
B28: ='General Journal'!C21 -> 45853 | C28: ='General Journal'!D21 -> Cost of goods sold | D28: ='General Journal'!E20 -> Cost of Goods Sold | F28: ='General Journal'!G21 -> 200000 | G28: =SUM($E$25:E28)-SUM($F$25:F28) -> 760000
D29: Closing balance | E29: =SUM(E25:E28) -> 1250000 | F29: =SUM(F25:F28) -> 490000 | G29: =E29-F29 -> 760000
B31: 1004 - Accounts Receivable - Mr. Rehman
B32: Date | C32: Description | D32: Contra Account | E32: Debit | F32: Credit | G32: Balance
B33: ='General Journal'!C14 -> 45848 | C33: ='General Journal'!D14 -> Inventory sold on credit | D33: ='General Journal'!E15 -> Sales Revenue | E33: ='General Journal'!F14 -> 800000 | G33: =SUM($E$33:E33)-SUM($F$33:F33) -> 800000
D34: Closing balance | E34: =SUM(E33:E33) -> 800000 | F34: =SUM(F33:F33) -> 0 | G34: =E34-F34 -> 800000
B36: 1101 - Computer Equipment
B37: Date | C37: Description | D37: Contra Account | E37: Debit | F37: Credit | G37: Balance
B38: ='General Journal'!C26 -> 45865 | C38: ='General Journal'!D26 -> Computer purchased | D38: ='General Journal'!E27 -> Bank | E38: ='General Journal'!F26 -> 250000 | G38: =SUM($E$38:E38)-SUM($F$38:F38) -> 250000
D39: Closing balance | E39: =SUM(E38:E38) -> 250000 | F39: =SUM(F38:F38) -> 0 | G39: =E39-F39 -> 250000
B41: 2001 - Accounts Payable - Mega Mart
B42: Date | C42: Description | D42: Contra Account | E42: Debit | F42: Credit | G42: Balance
B43: ='General Journal'!C11 -> 45843 | C43: ='General Journal'!D11 -> Inventory purchased on credit | D43: ='General Journal'!E10 -> Inventory | F43: ='General Journal'!G11 -> 750000 | G43: =SUM($E$43:E43)-SUM($F$43:F43) -> -750000
D44: Closing balance | E44: =SUM(E43:E43) -> 0 | F44: =SUM(F43:F43) -> 750000 | G44: =E44-F44 -> -750000
B46: 2002 - Income Tax Payable (Govt)
B47: Date | C47: Description | D47: Contra Account | E47: Debit | F47: Credit | G47: Balance
...

Sheet Trial Balance
B1: NEXORA INDUSTRIES LIMITED
B2: Trial Balance
B3: For the year ended 30 June 2026 | Amounts in PKR
B5: Code | C5: Account | D5: Category | E5: Total Debit | F5: Total Credit | G5: Debit Balance | H5: Credit Balance
B6: ='Chart of Accounts'!B6 -> 1001 | C6: ='Chart of Accounts'!C6 -> Cash in Hand | D6: ='Chart of Accounts'!D6 -> Asset | E6: =SUMIF('General Journal'!$E$6:$E$33,$C6,'General Journal'!$F$6:$F$33) -> 5425000 | F6: =SUMIF('General Journal'!$E$6:$E$33,$C6,'General Journal'!$G$6:$G$33) -> 1500000 | G6: =MAX(E6-F6,0) -> 3925000 | H6: =MAX(F6-E6,0) -> 0
B7: ='Chart of Accounts'!B7 -> 1002 | C7: ='Chart of Accounts'!C7 -> Bank | D7: ='Chart of Accounts'!D7 -> Asset | E7: =SUMIF('General Journal'!$E$6:$E$33,$C7,'General Journal'!$F$6:$F$33) -> 1500000 | F7: =SUMIF('General Journal'!$E$6:$E$33,$C7,'General Journal'!$G$6:$G$33) -> 1010000 | G7: =MAX(E7-F7,0) -> 490000 | H7: =MAX(F7-E7,0) -> 0
B8: ='Chart of Accounts'!B8 -> 1003 | C8: ='Chart of Accounts'!C8 -> Inventory | D8: ='Chart of Accounts'!D8 -> Asset | E8: =SUMIF('General Journal'!$E$6:$E$33,$C8,'General Journal'!$F$6:$F$33) -> 1250000 | F8: =SUMIF('General Journal'!$E$6:$E$33,$C8,'General Journal'!$G$6:$G$33) -> 490000 | G8: =MAX(E8-F8,0) -> 760000 | H8: =MAX(F8-E8,0) -> 0
B9: ='Chart of Accounts'!B9 -> 1004 | C9: ='Chart of Accounts'!C9 -> Accounts Receivable - Mr. Rehman | D9: ='Chart of Accounts'!D9 -> Asset | E9: =SUMIF('General Journal'!$E$6:$E$33,$C9,'General Journal'!$F$6:$F$33) -> 800000 | F9: =SUMIF('General Journal'!$E$6:$E$33,$C9,'General Journal'!$G$6:$G$33) -> 0 | G9: =MAX(E9-F9,0) -> 800000 | H9: =MAX(F9-E9,0) -> 0
B10: ='Chart of Accounts'!B10 -> 1101 | C10: ='Chart of Accounts'!C10 -> Computer Equipment | D10: ='Chart of Accounts'!D10 -> Asset | E10: =SUMIF('General Journal'!$E$6:$E$33,$C10,'General Journal'!$F$6:$F$33) -> 250000 | F10: =SUMIF('General Journal'!$E$6:$E$33,$C10,'General Journal'!$G$6:$G$33) -> 0 | G10: =MAX(E10-F10,0) -> 250000 | H10: =MAX(F10-E10,0) -> 0
B11: ='Chart of Accounts'!B11 -> 2001 | C11: ='Chart of Accounts'!C11 -> Accounts Payable - Mega Mart | D11: ='Chart of Accounts'!D11 -> Liability | E11: =SUMIF('General Journal'!$E$6:$E$33,$C11,'General Journal'!$F$6:$F$33) -> 0 | F11: =SUMIF('General Journal'!$E$6:$E$33,$C11,'General Journal'!$G$6:$G$33) -> 750000 | G11: =MAX(E11-F11,0) -> 0 | H11: =MAX(F11-E11,0) -> 750000
B12: ='Chart of Accounts'!B12 -> 2002 | C12: ='Chart of Accounts'!C12 -> Income Tax Payable (Govt) | D12: ='Chart of Accounts'!D12 -> Liability | E12: =SUMIF('General Journal'!$E$6:$E$33,$C12,'General Journal'!$F$6:$F$33) -> 0 | F12: =SUMIF('General Journal'!$E$6:$E$33,$C12,'General Journal'!$G$6:$G$33) -> 142500 | G12: =MAX(E12-F12,0) -> 0 | H12: =MAX(F12-E12,0) -> 142500
B13: ='Chart of Accounts'!B13 -> 3001 | C13: ='Chart of Accounts'!C13 -> Owner's Capital | D13: ='Chart of Accounts'!D13 -> Equity | E13: =SUMIF('General Journal'!$E$6:$E$33,$C13,'General Journal'!$F$6:$F$33) -> 0 | F13: =SUMIF('General Journal'!$E$6:$E$33,$C13,'General Journal'!$G$6:$G$33) -> 5000000 | G13: =MAX(E13-F13,0) -> 0 | H13: =MAX(F13-E13,0) -> 5000000
B14: ='Chart of Accounts'!B14 -> 4001 | C14: ='Chart of Accounts'!C14 -> Sales Revenue | D14: ='Chart of Accounts'!D14 -> Revenue | E14: =SUMIF('General Journal'!$E$6:$E$33,$C14,'General Journal'!$F$6:$F$33) -> 0 | F14: =SUMIF('General Journal'!$E$6:$E$33,$C14,'General Journal'!$G$6:$G$33) -> 1225000 | G14: =MAX(E14-F14,0) -> 0 | H14: =MAX(F14-E14,0) -> 1225000
B15: ='Chart of Accounts'!B15 -> 5001 | C15: ='Chart of Accounts'!C15 -> Cost of Goods Sold | D15: ='Chart of Accounts'!D15 -> Expense | E15: =SUMIF('General Journal'!$E$6:$E$33,$C15,'General Journal'!$F$6:$F$33) -> 490000 | F15: =SUMIF('General Journal'!$E$6:$E$33,$C15,'General Journal'!$G$6:$G$33) -> 0 | G15: =MAX(E15-F15,0) -> 490000 | H15: =MAX(F15-E15,0) -> 0
B16: ='Chart of Accounts'!B16 -> 5002 | C16: ='Chart of Accounts'!C16 -> Office Expenses | D16: ='Chart of Accounts'!D16 -> Expense | E16: =SUMIF('General Journal'!$E$6:$E$33,$C16,'General Journal'!$F$6:$F$33) -> 45000 | F16: =SUMIF('General Journal'!$E$6:$E$33,$C16,'General Journal'!$G$6:$G$33) -> 0 | G16: =MAX(E16-F16,0) -> 45000 | H16: =MAX(F16-E16,0) -> 0
B17: ='Chart of Accounts'!B17 -> 5003 | C17: ='Chart of Accounts'!C17 -> Entertainment Expenses | D17: ='Chart of Accounts'!D17 -> Expense | E17: =SUMIF('General Journal'!$E$6:$E$33,$C17,'General Journal'!$F$6:$F$33) -> 70000 | F17: =SUMIF('General Journal'!$E$6:$E$33,$C17,'General Journal'!$G$6:$G$33) -> 0 | G17: =MAX(E17-F17,0) -> 70000 | H17: =MAX(F17-E17,0) -> 0
... B20: ='Chart of Accounts'!B20 -> 5006 | C20: ='Chart of Accounts'!C20 -> Income Tax Expense | D20: ='Chart of Accounts'!D20 -> Expense | E20: =SUMIF('General Journal'!$E$6:$E$33,$C20,'General Journal'!$F$6:$F$33) -> 142500 | F20: =SUMIF('General Journal'!$E$6:$E$33,$C20,'General Journal'!$G$6:$G$33) -> 0 | G20: =MAX(E20-F20,0) -> 142500 | H20: =MAX(F20-E20,0) -> 0
C21: Total | E21: =SUM(E6:E20) -> 10117500 | F21: =SUM(F6:F20) -> 10117500 | G21: =SUM(G6:G20) -> 7117500 | H21: =SUM(H6:H20) -> 7117500
C22: Check (Debit Balance - Credit Balance, must be 0) | H22: =G21-H21 -> 0

Sheet Income Statement
B1: NEXORA INDUSTRIES LIMITED
B2: Income Statement
B3: For the year ended 30 June 2026 | Amounts in PKR
B5: Particulars | C5: PKR | D5: PKR
B6: Sales Revenue | D6: =SUMIF('Trial Balance'!$C$6:$C$20,$B6,'Trial Balance'!$H$6:$H$20)-SUMIF('Trial Balance'!$C$6:$C$20,$B6,'Trial Balance'!$G$6:$G$20) -> 1225000
B7: Cost of Goods Sold | D7: =-(SUMIF('Trial Balance'!$C$6:$C$20,$B7,'Trial Balance'!$G$6:$G$20)-SUMIF('Trial Balance'!$C$6:$C$20,$B7,'Trial Balance'!$H$6:$H$20)) -> -490000
B8: Gross Profit | D8: =D6+D7 -> 735000
B10: Operating Expenses
B11: Office Expenses | C11: =SUMIF('Trial Balance'!$C$6:$C$20,$B11,'Trial Balance'!$G$6:$G$20)-SUMIF('Trial Balance'!$C$6:$C$20,$B11,'Trial Balance'!$H$6:$H$20) -> 45000
B12: Rent Expense | C12: =SUMIF('Trial Balance'!$C$6:$C$20,$B12,'Trial Balance'!$G$6:$G$20)-SUMIF('Trial Balance'!$C$6:$C$20,$B12,'Trial Balance'!$H$6:$H$20) -> 35000
B13: Salary Expense | C13: =SUMIF('Trial Balance'!$C$6:$C$20,$B13,'Trial Balance'!$G$6:$G$20)-SUMIF('Trial Balance'!$C$6:$C$20,$B13,'Trial Balance'!$H$6:$H$20) -> 110000
B14: Entertainment Expenses | C14: =SUMIF('Trial Balance'!$C$6:$C$20,$B14,'Trial Balance'!$G$6:$G$20)-SUMIF('Trial Balance'!$C$6:$C$20,$B14,'Trial Balance'!$H$6:$H$20) -> 70000
B15: Total Operating Expenses | D15: =-SUM(C11:C14) -> -260000
B16: Operating Profit (Profit before Tax) | D16: =D8+D15 -> 475000
B17: Income Tax Expense @ | C17: 0.3 | D17: =-ROUND(D16*C17,0) -> -142500
B18: Net Profit for the Year | D18: =D16+D17 -> 332500
B20: Check: tax in journal vs tax computed here (must be 0) | D20: =-D17-(SUMIF('Trial Balance'!$C$6:$C$20,"Income Tax Expense",'Trial Balance'!$G$6:$G$20)-SUMIF('Trial Balance'!$C$6:$C$20,"Income Tax Expense",'Trial Balance'!$H$6:$H$20)) -> 0
B21: Yellow cell = tax-rate assumption (30%). Parentheses = deduction.

Sheet Balance Sheet
B1: NEXORA INDUSTRIES LIMITED
B2: Balance Sheet
B3: As at 30 June 2026 | Amounts in PKR
B5: Particulars | C5: PKR | D5: PKR
B6: ASSETS
B7: Non-Current Assets
B8: Computer Equipment | C8: =SUMIF('Trial Balance'!$C$6:$C$20,$B8,'Trial Balance'!$G$6:$G$20)-SUMIF('Trial Balance'!$C$6:$C$20,$B8,'Trial Balance'!$H$6:$H$20) -> 250000
B9: Total Non-Current Assets | D9: =C8 -> 250000
B10: Current Assets
B11: Cash in Hand | C11: =SUMIF('Trial Balance'!$C$6:$C$20,$B11,'Trial Balance'!$G$6:$G$20)-SUMIF('Trial Balance'!$C$6:$C$20,$B11,'Trial Balance'!$H$6:$H$20) -> 3925000
B12: Bank | C12: =SUMIF('Trial Balance'!$C$6:$C$20,$B12,'Trial Balance'!$G$6:$G$20)-SUMIF('Trial Balance'!$C$6:$C$20,$B12,'Trial Balance'!$H$6:$H$20) -> 490000
B13: Inventory | C13: =SUMIF('Trial Balance'!$C$6:$C$20,$B13,'Trial Balance'!$G$6:$G$20)-SUMIF('Trial Balance'!$C$6:$C$20,$B13,'Trial Balance'!$H$6:$H$20) -> 760000
B14: Accounts Receivable - Mr. Rehman | C14: =SUMIF('Trial Balance'!$C$6:$C$20,$B14,'Trial Balance'!$G$6:$G$20)-SUMIF('Trial Balance'!$C$6:$C$20,$B14,'Trial Balance'!$H$6:$H$20) -> 800000
B15: Total Current Assets | D15: =SUM(C11:C14) -> 5975000
B16: TOTAL ASSETS | D16: =D9+D15 -> 6225000
B18: LIABILITIES AND EQUITY
B19: Current Liabilities
B20: Accounts Payable - Mega Mart | C20: =SUMIF('Trial Balance'!$C$6:$C$20,$B20,'Trial Balance'!$H$6:$H$20)-SUMIF('Trial Balance'!$C$6:$C$20,$B20,'Trial Balance'!$G$6:$G$20) -> 750000
B21: Income Tax Payable (Govt) | C21: =SUMIF('Trial Balance'!$C$6:$C$20,$B21,'Trial Balance'!$H$6:$H$20)-SUMIF('Trial Balance'!$C$6:$C$20,$B21,'Trial Balance'!$G$6:$G$20) -> 142500
B22: Total Current Liabilities | D22: =SUM(C20:C21) -> 892500
B23: Equity
B24: Owner's Capital | C24: =SUMIF('Trial Balance'!$C$6:$C$20,$B24,'Trial Balance'!$H$6:$H$20)-SUMIF('Trial Balance'!$C$6:$C$20,$B24,'Trial Balance'!$G$6:$G$20) -> 5000000
B25: Net Profit for the Year | C25: ='Income Statement'!D18 -> 332500
B26: Total Equity | D26: =SUM(C24:C25) -> 5332500
B27: TOTAL LIABILITIES AND EQUITY | D27: =D22+D26 -> 6225000
B29: Balance check (Assets - Liabilities & Equity, must be 0) | D29: =D16-D27 -> 0
